Some weights of the model checkpoint at microsoft/deberta-v3-large were not used when initializing DebertaV2Model: ['mask_predictions.classifier.weight', 'lm_predictions.lm_head.LayerNorm.weight', 'lm_predictions.lm_head.dense.weight', 'lm_predictions.lm_head.bias', 'mask_predictions.classifier.bias', 'mask_predictions.LayerNorm.bias', 'lm_predictions.lm_head.LayerNorm.bias', 'mask_predictions.LayerNorm.weight', 'mask_predictions.dense.bias', 'lm_predictions.lm_head.dense.bias', 'mask_predictions.dense.weight']
- This IS expected if you are initializing DebertaV2Model from the checkpoint of a model trained on another task or with another architecture (e.g. initializing a BertForSequenceClassification model from a BertForPreTraining model).
- This IS NOT expected if you are initializing DebertaV2Model from the checkpoint of a model that you expect to be exactly identical (initializing a BertForSequenceClassification model from a BertForSequenceClassification model).
[1/5] Train & Validation
/home/qcqced/anaconda3/lib/python3.9/site-packages/transformers/optimization.py:391: FutureWarning: This implementation of AdamW is deprecated and will be removed in a future version. Use the PyTorch implementation torch.optim.AdamW instead, or set `no_deprecation_warning=True` to disable this warning
  warnings.warn(
  0%|                                                                                                             | 0/13928 [00:00<?, ?it/s]
Traceback (most recent call last):                                                                                | 0/13928 [00:00<?, ?it/s]
  File "/home/qcqced/바탕화면/ML_Test/GoogleAi4Code/train.py", line 23, in <module>
    main('googleai4code.json', CFG)
  File "/home/qcqced/바탕화면/ML_Test/GoogleAi4Code/train.py", line 19, in main
    getattr(train_loop, cfg.loop)(cfg)
  File "/home/qcqced/바탕화면/ML_Test/GoogleAi4Code/trainer/train_loop.py", line 34, in train_loop
    train_loss = train_input.train_fn(
  File "/home/qcqced/바탕화면/ML_Test/GoogleAi4Code/trainer/trainer.py", line 96, in train_fn
    for step, (prompt, ranks, all_position) in enumerate(tqdm(loader_train)):  # Maybe need to append
  File "/home/qcqced/anaconda3/lib/python3.9/site-packages/tqdm/std.py", line 1195, in __iter__
    for obj in iterable:
  File "/home/qcqced/anaconda3/lib/python3.9/site-packages/torch/utils/data/dataloader.py", line 633, in __next__
    data = self._next_data()
  File "/home/qcqced/anaconda3/lib/python3.9/site-packages/torch/utils/data/dataloader.py", line 1345, in _next_data
    return self._process_data(data)
  File "/home/qcqced/anaconda3/lib/python3.9/site-packages/torch/utils/data/dataloader.py", line 1371, in _process_data
    data.reraise()
  File "/home/qcqced/anaconda3/lib/python3.9/site-packages/torch/_utils.py", line 644, in reraise
    raise exception
RuntimeError: Caught RuntimeError in DataLoader worker process 0.
Original Traceback (most recent call last):
  File "/home/qcqced/anaconda3/lib/python3.9/site-packages/torch/utils/data/_utils/worker.py", line 308, in _worker_loop
    data = fetcher.fetch(index)
  File "/home/qcqced/anaconda3/lib/python3.9/site-packages/torch/utils/data/_utils/fetch.py", line 54, in fetch
    return self.collate_fn(data)
  File "/home/qcqced/anaconda3/lib/python3.9/site-packages/torch/utils/data/_utils/collate.py", line 265, in default_collate
    return collate(batch, collate_fn_map=default_collate_fn_map)
  File "/home/qcqced/anaconda3/lib/python3.9/site-packages/torch/utils/data/_utils/collate.py", line 142, in collate
    return [collate(samples, collate_fn_map=collate_fn_map) for samples in transposed]  # Backwards compatibility.
  File "/home/qcqced/anaconda3/lib/python3.9/site-packages/torch/utils/data/_utils/collate.py", line 142, in <listcomp>
    return [collate(samples, collate_fn_map=collate_fn_map) for samples in transposed]  # Backwards compatibility.
  File "/home/qcqced/anaconda3/lib/python3.9/site-packages/torch/utils/data/_utils/collate.py", line 119, in collate
    return collate_fn_map[elem_type](batch, collate_fn_map=collate_fn_map)
  File "/home/qcqced/anaconda3/lib/python3.9/site-packages/torch/utils/data/_utils/collate.py", line 162, in collate_tensor_fn
    return torch.stack(batch, 0, out=out)
RuntimeError: stack expects each tensor to be equal size, but got [32] at entry 0 and [24] at entry 1