Some weights of the model checkpoint at microsoft/deberta-v3-large were not used when initializing DebertaV2Model: ['lm_predictions.lm_head.LayerNorm.bias', 'mask_predictions.LayerNorm.bias', 'lm_predictions.lm_head.bias', 'mask_predictions.dense.weight', 'mask_predictions.classifier.weight', 'mask_predictions.classifier.bias', 'lm_predictions.lm_head.LayerNorm.weight', 'mask_predictions.LayerNorm.weight', 'mask_predictions.dense.bias', 'lm_predictions.lm_head.dense.bias', 'lm_predictions.lm_head.dense.weight']
- This IS expected if you are initializing DebertaV2Model from the checkpoint of a model trained on another task or with another architecture (e.g. initializing a BertForSequenceClassification model from a BertForPreTraining model).
- This IS NOT expected if you are initializing DebertaV2Model from the checkpoint of a model that you expect to be exactly identical (initializing a BertForSequenceClassification model from a BertForSequenceClassification model).
  0%|                                                                                                               | 0/803 [00:00<?, ?it/s]





































































































































































































































































































































































  5%|████▋                                                                                                  | 9/197 [00:01<00:38,  4.90it/s]
Traceback (most recent call last):                                                                          | 8/197 [00:01<00:25,  7.44it/s]
  File "/home/qcqced/바탕화면/ML_Test/GoogleAi4Code/train.py", line 22, in <module>
    main('dictionarywise_trainer.json', CFG)
  File "/home/qcqced/바탕화면/ML_Test/GoogleAi4Code/train.py", line 18, in main
    getattr(train_loop, cfg.loop)(cfg)
  File "/home/qcqced/바탕화면/ML_Test/GoogleAi4Code/trainer/train_loop.py", line 37, in train_loop
    valid_metric = train_input.valid_fn(
  File "/home/qcqced/바탕화면/ML_Test/GoogleAi4Code/trainer/trainer.py", line 155, in valid_fn
    val_metric = val_metric + val_metrics(
  File "/home/qcqced/anaconda3/lib/python3.9/site-packages/torch/nn/modules/module.py", line 1501, in _call_impl
    return forward_call(*args, **kwargs)
  File "/home/qcqced/바탕화면/ML_Test/GoogleAi4Code/model/metric.py", line 172, in forward
    ranks.append(gt.index(x))
ValueError: 0.00010607445437926799 is not in list